<?xml version="1.0"?>
<robot name="ur5">
  <link name="base_link" />

  <link name="base_link_inertia">
    <visual>
      <origin xyz="0 0 0" rpy="0 0 3.141592653589793" />
      <geometry>
        <mesh filename="meshes/ur5/visual/base.dae" />
      </geometry>
    </visual>
    <collision>
      <origin xyz="0 0 0" rpy="0 0 3.141592653589793" />
      <geometry>
        <mesh filename="meshes/ur5/collision/base.stl" />
      </geometry>
    </collision>
  </link>

  <link name="shoulder_link">
    <visual>
      <origin xyz="0 0 0" rpy="0 0 3.141592653589793" />
      <geometry>
        <mesh filename="meshes/ur5/visual/shoulder.dae" />
      </geometry>
    </visual>
    <collision>
      <origin xyz="0 0 0" rpy="0 0 3.141592653589793" />
      <geometry>
        <mesh filename="meshes/ur5/collision/shoulder.stl" />
      </geometry>
    </collision>
  </link>

  <link name="upper_arm_link">
    <visual>
      <origin xyz="0 0 0.13585" rpy="1.570796326794897 0 -1.570796326794897" />
      <geometry>
        <mesh filename="meshes/ur5/visual/upperarm.dae" />
      </geometry>
    </visual>
    <collision>
      <origin xyz="0 0 0.13585" rpy="1.570796326794897 0 -1.570796326794897" />
      <geometry>
        <mesh filename="meshes/ur5/collision/upperarm.stl" />
      </geometry>
    </collision>
  </link>

  <link name="forearm_link">
    <visual>
      <origin xyz="0 0 0.0165" rpy="1.570796326794897 0 -1.570796326794897" />
      <geometry>
        <mesh filename="meshes/ur5/visual/forearm.dae" />
      </geometry>
    </visual>
    <collision>
      <origin xyz="0 0 0.0165" rpy="1.570796326794897 0 -1.570796326794897" />
      <geometry>
        <mesh filename="meshes/ur5/collision/forearm.stl" />
      </geometry>
    </collision>
  </link>

  <link name="wrist_1_link">
    <visual>
      <origin xyz="0 0 -0.093" rpy="1.570796326794897 0 0" />
      <geometry>
        <mesh filename="meshes/ur5/visual/wrist1.dae" />
      </geometry>
    </visual>
    <collision>
      <origin xyz="0 0 -0.093" rpy="1.570796326794897 0 0" />
      <geometry>
        <mesh filename="meshes/ur5/collision/wrist1.stl" />
      </geometry>
    </collision>
  </link>

  <link name="wrist_2_link">
    <visual>
      <origin xyz="0 0 -0.095" rpy="0 0 0" />
      <geometry>
        <mesh filename="meshes/ur5/visual/wrist2.dae" />
      </geometry>
    </visual>
    <collision>
      <origin xyz="0 0 -0.095" rpy="0 0 0" />
      <geometry>
        <mesh filename="meshes/ur5/collision/wrist2.stl" />
      </geometry>
    </collision>
  </link>

  <link name="wrist_3_link">
    <visual>
      <origin xyz="0 0 -0.0818" rpy="1.570796326794897 0 0" />
      <geometry>
        <mesh filename="meshes/ur5/visual/wrist3.dae" />
      </geometry>
    </visual>
    <collision>
      <origin xyz="0 0 -0.0818" rpy="1.570796326794897 0 0" />
      <geometry>
        <mesh filename="meshes/ur5/collision/wrist3.stl" />
      </geometry>
    </collision>
  </link>

  <link name="base" />
  <link name="flange" />
  <link name="tool0" />

  <joint name="base_link-base_link_inertia" type="fixed">
    <parent link="base_link" />
    <child link="base_link_inertia" />
    <origin xyz="0 0 0" rpy="0 0 3.141592653589793" />
  </joint>

  <joint name="shoulder_pan_joint" type="revolute">
    <parent link="base_link_inertia" />
    <child link="shoulder_link" />
    <origin xyz="0 0 0.089159" rpy="0 0 0" />
    <axis xyz="0 0 1" />
    <limit lower="-6.283185307179586" upper="6.283185307179586" effort="150.0" velocity="3.141592653589793" />
  </joint>

  <joint name="shoulder_lift_joint" type="revolute">
    <parent link="shoulder_link" />
    <child link="upper_arm_link" />
    <origin xyz="0 0 0" rpy="1.570796327 0 0" />
    <axis xyz="0 0 1" />
    <limit lower="-6.283185307179586" upper="6.283185307179586" effort="150.0" velocity="3.141592653589793" />
  </joint>

  <joint name="elbow_joint" type="revolute">
    <parent link="upper_arm_link" />
    <child link="forearm_link" />
    <origin xyz="-0.425 0 0" rpy="0 0 0" />
    <axis xyz="0 0 1" />
    <limit lower="-3.141592653589793" upper="3.141592653589793" effort="150.0" velocity="3.141592653589793" />
  </joint>

  <joint name="wrist_1_joint" type="revolute">
    <parent link="forearm_link" />
    <child link="wrist_1_link" />
    <origin xyz="-0.39225 0 0.10915" rpy="0 0 0" />
    <axis xyz="0 0 1" />
    <limit lower="-6.283185307179586" upper="6.283185307179586" effort="28.0" velocity="3.141592653589793" />
  </joint>

  <joint name="wrist_2_joint" type="revolute">
    <parent link="wrist_1_link" />
    <child link="wrist_2_link" />
    <origin xyz="0 -0.09465 -1.941303950897609e-11" rpy="1.570796327 0 0" />
    <axis xyz="0 0 1" />
    <limit lower="-6.283185307179586" upper="6.283185307179586" effort="28.0" velocity="3.141592653589793" />
  </joint>

  <joint name="wrist_3_joint" type="revolute">
    <parent link="wrist_2_link" />
    <child link="wrist_3_link" />
    <origin xyz="0 0.0823 -1.688001216681175e-11" rpy="1.570796326589793 3.141592653589793 3.141592653589793" />
    <axis xyz="0 0 1" />
    <limit lower="-6.283185307179586" upper="6.283185307179586" effort="28.0" velocity="3.141592653589793" />
  </joint>

  <joint name="base_link-base_fixed_joint" type="fixed">
    <parent link="base_link" />
    <child link="base" />
    <origin xyz="0 0 0" rpy="0 0 3.141592653589793" />
  </joint>

  <joint name="wrist_3-flange" type="fixed">
    <parent link="wrist_3_link" />
    <child link="flange" />
    <origin xyz="0 0 0" rpy="0 -1.570796326794897 -1.570796326794897" />
  </joint>

  <joint name="flange-tool0" type="fixed">
    <parent link="flange" />
    <child link="tool0" />
    <origin xyz="0 0 0" rpy="1.570796326794897 0 1.570796326794897" />
  </joint>
</robot>
